Workbook

Sheet README
A1: SALES DATA ANALYSIS & EXECUTIVE KPI DASHBOARD
A3: Portfolio Project Documentation | Prepared for Product Analyst & Business Intelligence Demonstration
A5: 1. EXECUTIVE SUMMARY & BUSINESS OBJECTIVES
A6: Business Problem | B6: A multi-channel retail company operating across three categories (Technology, Furniture, and Office Supplies) requires end-to-end sales and profitability visibility. Rapid revenue growth during promotional events has led to suspected margin erosion due to unmonitored discounting and sub-optimal regional performance.
A7: Core Objective | B7: Analyze 1,000 retail transactions across products, categories, sales channels, and geographic regions. Convert raw sales data into actionable commercial insights, identify margin compression drivers, and deliver an interactive, executive-ready Excel dashboard.
A8: Target Audience | B8: VP of Product, Head of Commercial Operations, Category Managers, and Sales Directors.
A10: 2. DATASET ARCHITECTURE & TECHNICAL STACK
A11: Dataset Scope | B11: 1,000 validated transactions, 730 unique orders across FY 2024 (Jan 1, 2024 - Dec 31, 2024). Multi-item baskets reflect realistic retail ordering behavior.
A12: Primary Tool | B12: Microsoft Excel 365 (Tables, Dynamic Array Formulas, Pivot Summaries, KPI Cards, Slicers, Native Visualizations).
A13: Validation Engine | B13: Python 3.13 with Pandas for secondary reconciliation and automated anomaly auditing.
A14: Key Columns | B14: Order ID, Order Date, Product ID, Product Name, Category, Subcategory, Region, State, Sales Channel, Customer Segment, Quantity, Unit Price, Discount %, Unit Cost, Gross Sales, Discount Amount, Net Sales, Total Cost, Profit, Profit Margin.
A16: 3. CORE KPI DEFINITIONS & FORMULAS
A17: Total Net Sales | B17: Total revenue realized after all promotional discounts. Formula: =SUM(Net_Sales) | [Gross Sales - Discount Amount].
A18: Total Unique Orders | B18: True count of unique customer orders, not simply row count. In Excel: =SUMPRODUCT(1/COUNTIF(OrderID, OrderID)) or Distinct Count in PivotTable.
A19: Total Units Sold | B19: Sum of all product units purchased. Formula: =SUM(Quantity).
A20: Total Net Profit | B20: Bottom-line dollar profit remaining after cost of goods sold. Formula: =SUM(Profit) | [Net Sales - Total Cost].
A21: Average Order Value (AOV) | B21: Average net revenue generated per unique purchase order. Formula: Total Net Sales / Total Unique Orders ($1,042,276 / 730 = $1,427.78).
A22: Profit Margin % | B22: Overall operational profitability percentage. Formula: =IFERROR(Total Profit / Total Net Sales, 0) (15.75%).
A23: Sales-Weighted Discount | B23: Total dollars discounted relative to total gross catalog value. Formula: =SUM(Discount Amount) / SUM(Gross Sales) (9.68%). Distinct from simple average discount (6.30%).
A24: MoM Sales Growth % | B24: Month-over-month trajectory in net revenue. Formula: =(Net_Sales_Curr - Net_Sales_Prior) / Net_Sales_Prior.
A26: 4. WORKBOOK NAVIGATION GUIDE
A27: Sheet: Raw_Data | B27: Contains original 1,004 raw transaction records (including 10 injected real-world anomalies for data cleaning demonstration). Formatted as table 'SalesData'.
A28: Sheet: Clean_Data | B28: Contains 1,000 cleaned, standardized, and formula-derived records. Formatted as table 'CleanSalesData'.
A29: Sheet: Data_Quality | B29: Automated data hygiene audit sheet displaying exception counts, validation test rules, and row-by-row remediation log.
A30: Sheet: Pivot_Analysis | B30: Structured analytical tables providing pre-aggregated breakdowns across Months, Categories, Products, Regions, Channels, and Discount Tiers.
A31: Sheet: Dashboard | B31: High-impact visual executive dashboard with 6 KPI cards, 6 dynamic charts, and interactive slicer instructions.
A32: Sheet: Business_Insights | B32: Structured executive findings report answering key strategic questions with concrete data evidence and recommended actions.
A34: 5. KEY ASSUMPTIONS & METHODOLOGICAL LIMITATIONS
A35: Synthetic Generation | B35: All transaction data is synthetically generated for educational and portfolio demonstration purposes, reflecting realistic retail statistical properties.
A36: Cost Basis | B36: Unit Cost represents fully burdened landed cost of goods. Return rates and corporate tax overhead are excluded from gross margin modeling.
A37: Discounting Model | B37: Discounts are applied per line-item transaction. Bulk order rebates are mapped into the Wholesale channel price structure.

Sheet Raw_Data
A1: Order ID | B1: Order Date | C1: Product ID | D1: Product Name | E1: Category | F1: Subcategory | G1: Region | H1: State | I1: Sales Channel | J1: Customer Segment | K1: Quantity | L1: Unit Price | M1: Discount Percentage | N1: Unit Cost | O1: Gross Sales | P1: Discount Amount | Q1: Net Sales | R1: Total Cost | S1: Profit | T1: Profit Margin
A2: ORD-2024-1053 | B2: 2024-01-02 | C2: FUR-DSK-003 | D2: ApexMotor Dual-Motor Standing Desk | E2: Furniture | F2: Desks & Workstations | G2: South | H2: Virginia | I2: Retail Partner | J2: Corporate | K2: 8 | L2: 549.99 | M2: 0 | N2: 439.99 | O2: 4399.92 | P2: 0 | Q2: 4399.92 | R2: 3519.92 | S2: 880 | T2: 0.2
A3: ORD-2024-1381 | B3: 2024-01-03 | C3: TEC-ACC-008 | D3: Precision Laser Bluetooth Mouse | E3: Technology | F3: Audio & Accessories | G3: Central | H3: Ohio | I3: Direct Sales | J3: Consumer | K3: 1 | L3: 49.99 | M3: 0 | N3: 27.49 | O3: 49.99 | P3: 0 | Q3: 49.99 | R3: 27.49 | S3: 22.5 | T3: 0.4501
A4: ORD-2024-1381 | B4: 2024-01-03 | C4: FUR-DSK-003 | D4: ApexMotor Dual-Motor Standing Desk | E4: Furniture | F4: Desks & Workstations | G4: Central | H4: Ohio | I4: Direct Sales | J4: Consumer | K4: 1 | L4: 549.99 | M4: 0.15 | N4: 439.99 | O4: 549.99 | P4: 82.5 | Q4: 467.49 | R4: 439.99 | S4: 27.5 | T4: 0.0588
A5: ORD-2024-1691 | B5: 2024-01-03 | C5: FUR-BOK-005 | D5: Modular 5-Tier Steel Bookcase | E5: Furniture | F5: Bookcases | G5: South | H5: Florida | I5: Retail Partner | J5: Consumer | K5: 3 | L5: 189.99 | M5: 0 | N5: 142.49 | O5: 569.97 | P5: 0 | Q5: 569.97 | R5: 427.47 | S5: 142.5 | T5: 0.25
A6: ORD-2024-1095 | B6: 2024-01-06 | C6: TEC-LAP-002 | D6: Apex Gaming Laptop 17" | E6: Technology | F6: Laptops | G6: Central | H6: Ohio | I6: Direct Sales | J6: Consumer | K6: 1 | L6: 1499.99 | M6: 0.25 | N6: 1259.99 | O6: 1499.99 | P6: 375 | Q6: 1124.99 | R6: 1259.99 | S6: -135 | T6: -0.12
A7: ORD-2024-1095 | B7: 2024-01-06 | C7: OFF-ART-006 | D7: Professional Presentation Dry Erase Board | E7: Office Supplies | F7: Presentation & Art | G7: Central | H7: Ohio | I7: Direct Sales | J7: Consumer | K7: 4 | L7: 89.99 | M7: 0 | N7: 53.99 | O7: 359.96 | P7: 0 | Q7: 359.96 | R7: 215.96 | S7: 144 | T7: 0.4
A8: ORD-2024-1055 | B8: 2024-01-07 | C8: TEC-ACC-005 | D8: UltraWireless Noise-Canceling Headset | E8: Technology | F8: Audio & Accessories | G8: East | H8: New Jersey | I8: Direct Sales | J8: Corporate | K8: 5 | L8: 179.99 | M8: 0.05 | N8: 111.59 | O8: 899.95 | P8: 45 | Q8: 854.95 | R8: 557.95 | S8: 297 | T8: 0.3474
A9: ORD-2024-1055 | B9: 2024-01-07 | C9: TEC-ACC-006 | D9: MultiPort Thunderbolt 4 Dock | E9: Technology | F9: Audio & Accessories | G9: East | H9: New Jersey | I9: Direct Sales | J9: Corporate | K9: 4 | L9: 149.99 | M9: 0 | N9: 98.99 | O9: 599.96 | P9: 0 | Q9: 599.96 | R9: 395.96 | S9: 204 | T9: 0.34
A10: ORD-2024-1275 | B10: 2024-01-07 | C10: OFF-STR-001 | D10: SteelLock 3-Drawer File Cabinet | E10: Office Supplies | F10: Storage & Organizers | G10: West | H10: Colorado | I10: Wholesale | J10: Home Office | K10: 8 | L10: 169.99 | M10: 0.15 | N10: 115.59 | O10: 1359.92 | P10: 203.99 | Q10: 1155.93 | R10: 924.72 | S10: 231.21 | T10: 0.2
A11: ORD-2024-1275 | B11: 2024-01-07 | C11: FUR-DSK-004 | D11: Metro Compact Corner Workstation | E11: Furniture | F11: Desks & Workstations | G11: West | H11: Colorado | I11: Wholesale | J11: Home Office | K11: 6 | L11: 329.99 | M11: 0.1 | N11: 250.79 | O11: 1979.94 | P11: 197.99 | Q11: 1781.95 | R11: 1504.74 | S11: 277.21 | T11: 0.1556
A12: ORD-2024-1275 | B12: 2024-01-07 | C12: OFF-DSK-008 | D12: Steel Desktop Mesh Organizer Caddy | E12: Office Supplies | F12: Desk Supplies | G12: West | H12: Colorado | I12: Wholesale | J12: Home Office | K12: 10 | L12: 18.99 | M12: 0.15 | N12: 8.55 | O12: 189.9 | P12: 28.48 | Q12: 161.42 | R12: 85.5 | S12: 75.92 | T12: 0.4703
A13: ORD-2024-1570 | B13: 2024-01-07 | C13: TEC-ACC-008 | D13: Precision Laser Bluetooth Mouse | E13: Technology | F13: Audio & Accessories | G13: South | H13: North Carolina | I13: Retail Partner | J13: Corporate | K13: 5 | L13: 49.99 | M13: 0 | N13: 27.49 | O13: 249.95 | P13: 0 | Q13: 249.95 | R13: 137.45 | S13: 112.5 | T13: 0.4501
... A51: ORD-2024-1141 | B51: 2024-01-24 | C51: FUR-DSK-004 | D51: Metro Compact Corner Workstation | E51: Furniture | F51: Desks & Workstations | G51: West | H51: California | I51: Direct Sales | J51: Consumer | K51: 2 | L51: 329.99 | M51: 0.1 | N51: 250.79 | O51: 659.98 | P51: 66 | Q51: 593.98 | R51: 501.58 | S51: 92.4 | T51: 0.1556
A52: ORD-2024-1141 | B52: 2024-01-24 | C52: OFF-DSK-007 | D52: Gel Ergo Mouse Pad & Wrist Rest Combo | E52: Office Supplies | F52: Desk Supplies | G52: West | H52: California | I52: Direct Sales | K52: 1 | L52: 21.99 | M52: 0 | N52: 10.56 | O52: 21.99 | P52: 0 | Q52: 21.99 | R52: 10.56 | S52: 11.43 | T52: 0.5198
A53: ORD-2024-1410 | B53: 2024-01-24 | C53: OFF-ART-006 | D53: Professional Presentation Dry Erase Board | E53: Office Supplies | F53: Presentation & Art | G53: West | H53: Oregon | I53: Retail Partner | J53: Consumer | K53: 4 | L53: 89.99 | M53: 0 | N53: 53.99 | O53: 359.96 | P53: 0 | Q53: 359.96 | R53: 215.96 | S53: 144 | T53: 0.4
A54: ORD-2024-1315 | B54: 2024-01-25 | C54: TEC-LAP-002 | D54: Apex Gaming Laptop 17" | E54: Technology | F54: Laptops | G54: West | H54: California | I54: Wholesale | J54: Consumer | K54: 7 | L54: 1499.99 | M54: 0.15 | N54: 1259.99 | O54: 10499.93 | P54: 1574.99 | Q54: 8924.94 | R54: 8819.93 | S54: 105.01 | T54: 0.0118
A55: ORD-2024-1536 | B55: 2024-01-25 | C55: FUR-CHA-002 | D55: AeroTask Operator Task Chair | E55: Furniture | F55: Chairs | G55: East | H55: New York | I55: Retail Partner | J55: Corporate | K55: 5 | L55: 219.99 | M55: 0.05 | N55: 171.59 | O55: 1099.95 | P55: 55 | Q55: 1044.95 | R55: 857.95 | S55: 187 | T55: 0.179
A56: ORD-2024-1230 | B56: 2024-01-26 | C56: FUR-DSK-003 | D56: ApexMotor Dual-Motor Standing Desk | E56: Furniture | F56: Desks & Workstations | G56: South | H56: North Carolina | I56: Online | J56: Home Office | K56: 4 | L56: 549.99 | M56: 0.05 | N56: 439.99 | O56: 2199.96 | P56: 110 | Q56: 2089.96 | R56: 1759.96 | S56: 330 | T56: 0.1579
A57: ORD-2024-1230 | B57: 2024-01-26 | C57: OFF-DSK-007 | D57: Gel Ergo Mouse Pad & Wrist Rest Combo | E57: Office Supplies | F57: Desk Supplies | G57: South | H57: North Carolina | I57: Online | J57: Home Office | K57: 1 | L57: 21.99 | M57: 0.05 | N57: 10.56 | O57: 21.99 | P57: 1.1 | Q57: 20.89 | R57: 10.56 | S57: 10.33 | T57: 0.4945
A58: ORD-2024-1388 | B58: 2024-01-27 | C58: OFF-ART-006 | D58: Professional Presentation Dry Erase Board | E58: Office Supplies | F58: Presentation & Art | G58: East | H58: New Jersey | I58: Direct Sales | J58: Consumer | K58: 1 | L58: 89.99 | M58: 0.1 | N58: 53.99 | O58: 89.99 | P58: 9 | Q58: 80.99 | R58: 53.99 | S58: 27 | T58: 0.3334
A59: ORD-2024-1388 | B59: 2024-01-27 | C59: OFF-DSK-007 | D59: Gel Ergo Mouse Pad & Wrist Rest Combo | E59: Office Supplies | F59: Desk Supplies | G59: East | H59: New Jersey | I59: Direct Sales | J59: Consumer | K59: 2 | L59: 21.99 | M59: 0.05 | N59: 10.56 | O59: 43.98 | P59: 2.2 | Q59: 41.78 | R59: 21.12 | S59: 20.66 | T59: 0.4945
A60: ORD-2024-1388 | B60: 2024-01-27 | C60: TEC-ACC-005 | D60: UltraWireless Noise-Canceling Headset | E60: Technology | F60: Audio & Accessories | G60: East | H60: New Jersey | I60: Direct Sales | J60: Consumer | K60: 3 | L60: 179.99 | M60: 0 | N60: 111.59 | O60: 539.97 | P60: 0 | Q60: 539.97 | R60: 334.77 | S60: 205.2 | T60: 0.38
A61: ORD-2024-1033 | B61: 2024-01-28 | C61: OFF-DSK-007 | D61: Gel Ergo Mouse Pad & Wrist Rest Combo | E61: Office Supplies | F61: Desk Supplies | G61: West | H61: Oregon | I61: Direct Sales | J61: Corporate | K61: 6 | L61: 21.99 | M61: 0 | N61: 10.56 | O61: 131.94 | P61: 0 | Q61: 131.94 | R61: 63.36 | S61: 68.58 | T61: 0.5198
A62: ORD-2024-1223 | B62: 2024-01-28 | C62: TEC-ACC-008 | D62: Precision Laser Bluetooth Mouse | E62: Technology | F62: Audio & Accessories | G62: West | H62: Washington | I62: Wholesale | J62: Home Office | K62: 14 | L62: 49.99 | M62: 0.2 | N62: 27.49 | O62: 699.86 | P62: 139.97 | Q62: 559.89 | R62: 384.86 | S62: 175.03 | T62: 0.3126
A63: ORD-2024-1377 | B63: 2024-01-29 | C63: FUR-LGT-006 | D63: Architect LED Desk Task Lamp | E63: Furniture | F63: Lighting | G63: Central | H63: Texas | I63: Direct Sales | J63: Consumer | K63: 1 | L63: 69.99 | M63: 0 | N63: 43.39 | O63: 69.99 | P63: 0 | Q63: 69.99 | R63: 43.39 | S63: 26.6 | T63: 0.3801
A64: ORD-2024-1073 | B64: 2024-01-30 | C64: TEC-ACC-005 | D64: UltraWireless Noise-Canceling Headset | E64: Technology | F64: Audio & Accessories | G64: South | H64: Florida | I64: Online | J64: Home Office | K64: 3 | L64: 179.99 | M64: 0.15 | N64: 111.59 | O64: 539.97 | P64: 81 | Q64: 458.97 | R64: 334.77 | S64: 124.2 | T64: 0.2706
... A313: ORD-2024-1155 | B313: 2024-05-15 | C313: FUR-LGT-006 | D313: Architect LED Desk Task Lamp | E313: Furniture | F313: Lighting | G313: Central | H313: Texas | I313: Retail Partner | J313: Corporate | K313: 3 | L313: 69.99 | M313: 0.05 | N313: 43.39 | O313: 209.97 | P313: 10.5 | Q313: 199.47 | R313: 130.17 | S313: 69.3 | T313: 0.3474
A314: ORD-2024-1314 | B314: 2024-05-15 | C314: TEC-ACC-006 | D314: MultiPort Thunderbolt 4 Dock | E314: Technology | F314: Audio & Accessories | G314: West | H314: Oregon | I314: Retail Partner | K314: 3 | L314: 149.99 | M314: 0 | N314: 98.99 | O314: 449.97 | P314: 0 | Q314: 449.97 | R314: 296.97 | S314: 153 | T314: 0.34
A315: ORD-2024-1314 | B315: 2024-05-15 | C315: FUR-CHA-002 | D315: AeroTask Operator Task Chair | E315: Furniture | F315: Chairs | G315: West | H315: Oregon | I315: Retail Partner | J315: Consumer | K315: 3 | L315: 219.99 | M315: 0 | N315: 171.59 | O315: 659.97 | P315: 0 | Q315: 659.97 | R315: 514.77 | S315: 145.2 | T315: 0.22
A316: ORD-2024-1470 | B316: 2024-05-16 | C316: FUR-DSK-004 | D316: Metro Compact Corner Workstation | E316: Furniture | F316: Desks & Workstations | G316: South | H316: Florida | I316: Retail Partner | J316: Corporate | K316: 4 | L316: 329.99 | M316: 0.05 | N316: 250.79 | O316: 1319.96 | P316: 66 | Q316: 1253.96 | R316: 1003.16 | S316: 250.8 | T316: 0.2
A317: ORD-2024-1668 | B317: 2024-05-16 | C317: TEC-ACC-005 | D317: UltraWireless Noise-Canceling Headset | E317: Technology | F317: Audio & Accessories | G317: West | H317: Oregon | I317: Direct Sales | J317: Home Office | K317: 2 | L317: 179.99 | M317: 0 | N317: 111.59 | O317: 359.98 | P317: 0 | Q317: 359.98 | R317: 223.18 | S317: 136.8 | T317: 0.38
A318: ORD-2024-1018 | B318: 2024-05-18 | C318: TEC-ACC-006 | D318: MultiPort Thunderbolt 4 Dock | E318: Technology | F318: Audio & Accessories | G318: West | H318: Washington | I318: Wholesale | J318: Home Office | K318: 12 | L318: 149.99 | M318: 0.2 | N318: 98.99 | O318: 1799.88 | P318: 359.98 | Q318: 1439.9 | R318: 1187.88 | S318: 252.02 | T318: 0.175
A319: ORD-2024-1590 | B319: 2024-05-18 | C319: TEC-LAP-002 | D319: Apex Gaming Laptop 17" | E319: Technology | F319: Laptops | G319: West | H319: Colorado | I319: Online | J319: Consumer | K319: 1 | L319: 1499.99 | M319: 0.25 | N319: 1259.99 | O319: 1499.99 | P319: 375 | Q319: 1124.99 | R319: 1259.99 | S319: -135 | T319: -0.12
A320: ORD-2024-1147 | B320: 2024-05-19 | C320: FUR-CHA-002 | D320: AeroTask Operator Task Chair | E320: Furniture | F320: Chairs | G320: East | H320: New York | I320: Direct Sales | J320: Home Office | K320: 4 | L320: 219.99 | M320: 0 | N320: 171.59 | O320: 879.96 | P320: 0 | Q320: 879.96 | R320: 686.36 | S320: 193.6 | T320: 0.22
A321: ORD-2024-1630 | B321: 2024-05-19 | C321: OFF-DSK-008 | D321: Steel Desktop Mesh Organizer Caddy | E321: Office Supplies | F321: Desk Supplies | G321: East | H321: Pennsylvania | I321: Online | J321: Corporate | K321: 8 | L321: 18.99 | M321: 0 | N321: 8.55 | O321: 151.92 | P321: 0 | Q321: 151.92 | R321: 68.4 | S321: 83.52 | T321: 0.5498
A322: ORD-2024-1624 | B322: 2024-05-20 | C322: FUR-DSK-003 | D322: ApexMotor Dual-Motor Standing Desk | E322: Furniture | F322: Desks & Workstations | G322: West | H322: Colorado | I322: Direct Sales | J322: Consumer | K322: 4 | L322: 549.99 | M322: 0 | N322: 439.99 | O322: 2199.96 | P322: 0 | Q322: 2199.96 | R322: 1759.96 | S322: 440 | T322: 0.2
A323: ORD-2024-1624 | B323: 2024-05-20 | C323: FUR-DSK-003 | D323: ApexMotor Dual-Motor Standing Desk | E323: Furniture | F323: Desks & Workstations | G323: West | H323: Colorado | I323: Direct Sales | J323: Consumer | K323: 4 | L323: 549.99 | M323: 0 | N323: 439.99 | O323: 2199.96 | P323: 0 | Q323: 2199.96 | R323: 1759.96 | S323: 440 | T323: 0.2
A324: ORD-2024-1624 | B324: 2024-05-20 | C324: OFF-DSK-007 | D324: Gel Ergo Mouse Pad & Wrist Rest Combo | E324: Office Supplies | F324: Desk Supplies | G324: West | H324: Colorado | I324: Direct Sales | J324: Consumer | K324: 2 | L324: 21.99 | M324: 0.05 | N324: 10.56 | O324: 43.98 | P324: 2.2 | Q324: 41.78 | R324: 21.12 | S324: 20.66 | T324: 0.4945
A325: ORD-2024-1639 | B325: 2024-05-20 | C325: OFF-BIN-005 | D325: Heavy-Duty D-Ring Presentation Binder (6-Pk) | E325: Office Supplies | F325: Binders & Fasteners | G325: South | H325: Florida | I325: Online | J325: Consumer | K325: 4 | L325: 27.99 | M325: 0.05 | N325: 13.99 | O325: 111.96 | P325: 5.6 | Q325: 106.36 | R325: 55.96 | S325: 50.4 | T325: 0.4739
...

Sheet Clean_Data
A1: Order ID | B1: Order Date | C1: Product ID | D1: Product Name | E1: Category | F1: Subcategory | G1: Region | H1: State | I1: Sales Channel | J1: Customer Segment | K1: Quantity | L1: Unit Price | M1: Discount Percentage | N1: Unit Cost | O1: Gross Sales | P1: Discount Amount | Q1: Net Sales | R1: Total Cost | S1: Profit | T1: Profit Margin
A2: ORD-2024-1053 | B2: 2024-01-02 | C2: FUR-DSK-003 | D2: ApexMotor Dual-Motor Standing Desk | E2: Furniture | F2: Desks & Workstations | G2: South | H2: Virginia | I2: Retail Partner | J2: Corporate | K2: 8 | L2: 549.99 | M2: 0 | N2: 439.99 | O2: =K2*L2 | P2: =O2*M2 | Q2: =O2-P2 | R2: =K2*N2 | S2: =Q2-R2 | T2: =IFERROR(S2/Q2, 0)
A3: ORD-2024-1381 | B3: 2024-01-03 | C3: TEC-ACC-008 | D3: Precision Laser Bluetooth Mouse | E3: Technology | F3: Audio & Accessories | G3: Central | H3: Ohio | I3: Direct Sales | J3: Consumer | K3: 1 | L3: 49.99 | M3: 0 | N3: 27.49 | O3: =K3*L3 | P3: =O3*M3 | Q3: =O3-P3 | R3: =K3*N3 | S3: =Q3-R3 | T3: =IFERROR(S3/Q3, 0)
A4: ORD-2024-1381 | B4: 2024-01-03 | C4: FUR-DSK-003 | D4: ApexMotor Dual-Motor Standing Desk | E4: Furniture | F4: Desks & Workstations | G4: Central | H4: Ohio | I4: Direct Sales | J4: Consumer | K4: 1 | L4: 549.99 | M4: 0.15 | N4: 439.99 | O4: =K4*L4 | P4: =O4*M4 | Q4: =O4-P4 | R4: =K4*N4 | S4: =Q4-R4 | T4: =IFERROR(S4/Q4, 0)
A5: ORD-2024-1691 | B5: 2024-01-03 | C5: FUR-BOK-005 | D5: Modular 5-Tier Steel Bookcase | E5: Furniture | F5: Bookcases | G5: South | H5: Florida | I5: Retail Partner | J5: Consumer | K5: 3 | L5: 189.99 | M5: 0 | N5: 142.49 | O5: =K5*L5 | P5: =O5*M5 | Q5: =O5-P5 | R5: =K5*N5 | S5: =Q5-R5 | T5: =IFERROR(S5/Q5, 0)
A6: ORD-2024-1095 | B6: 2024-01-06 | C6: TEC-LAP-002 | D6: Apex Gaming Laptop 17" | E6: Technology | F6: Laptops | G6: Central | H6: Ohio | I6: Direct Sales | J6: Consumer | K6: 1 | L6: 1499.99 | M6: 0.25 | N6: 1259.99 | O6: =K6*L6 | P6: =O6*M6 | Q6: =O6-P6 | R6: =K6*N6 | S6: =Q6-R6 | T6: =IFERROR(S6/Q6, 0)
A7: ORD-2024-1095 | B7: 2024-01-06 | C7: OFF-ART-006 | D7: Professional Presentation Dry Erase Board | E7: Office Supplies | F7: Presentation & Art | G7: Central | H7: Ohio | I7: Direct Sales | J7: Consumer | K7: 4 | L7: 89.99 | M7: 0 | N7: 53.99 | O7: =K7*L7 | P7: =O7*M7 | Q7: =O7-P7 | R7: =K7*N7 | S7: =Q7-R7 | T7: =IFERROR(S7/Q7, 0)
A8: ORD-2024-1055 | B8: 2024-01-07 | C8: TEC-ACC-005 | D8: UltraWireless Noise-Canceling Headset | E8: Technology | F8: Audio & Accessories | G8: East | H8: New Jersey | I8: Direct Sales | J8: Corporate | K8: 5 | L8: 179.99 | M8: 0.05 | N8: 111.59 | O8: =K8*L8 | P8: =O8*M8 | Q8: =O8-P8 | R8: =K8*N8 | S8: =Q8-R8 | T8: =IFERROR(S8/Q8, 0)
A9: ORD-2024-1055 | B9: 2024-01-07 | C9: TEC-ACC-006 | D9: MultiPort Thunderbolt 4 Dock | E9: Technology | F9: Audio & Accessories | G9: East | H9: New Jersey | I9: Direct Sales | J9: Corporate | K9: 4 | L9: 149.99 | M9: 0 | N9: 98.99 | O9: =K9*L9 | P9: =O9*M9 | Q9: =O9-P9 | R9: =K9*N9 | S9: =Q9-R9 | T9: =IFERROR(S9/Q9, 0)
A10: ORD-2024-1275 | B10: 2024-01-07 | C10: OFF-STR-001 | D10: SteelLock 3-Drawer File Cabinet | E10: Office Supplies | F10: Storage & Organizers | G10: West | H10: Colorado | I10: Wholesale | J10: Home Office | K10: 8 | L10: 169.99 | M10: 0.15 | N10: 115.59 | O10: =K10*L10 | P10: =O10*M10 | Q10: =O10-P10 | R10: =K10*N10 | S10: =Q10-R10 | T10: =IFERROR(S10/Q10, 0)
A11: ORD-2024-1275 | B11: 2024-01-07 | C11: FUR-DSK-004 | D11: Metro Compact Corner Workstation | E11: Furniture | F11: Desks & Workstations | G11: West | H11: Colorado | I11: Wholesale | J11: Home Office | K11: 6 | L11: 329.99 | M11: 0.1 | N11: 250.79 | O11: =K11*L11 | P11: =O11*M11 | Q11: =O11-P11 | R11: =K11*N11 | S11: =Q11-R11 | T11: =IFERROR(S11/Q11, 0)
A12: ORD-2024-1275 | B12: 2024-01-07 | C12: OFF-DSK-008 | D12: Steel Desktop Mesh Organizer Caddy | E12: Office Supplies | F12: Desk Supplies | G12: West | H12: Colorado | I12: Wholesale | J12: Home Office | K12: 10 | L12: 18.99 | M12: 0.15 | N12: 8.55 | O12: =K12*L12 | P12: =O12*M12 | Q12: =O12-P12 | R12: =K12*N12 | S12: =Q12-R12 | T12: =IFERROR(S12/Q12, 0)
A13: ORD-2024-1570 | B13: 2024-01-07 | C13: TEC-ACC-008 | D13: Precision Laser Bluetooth Mouse | E13: Technology | F13: Audio & Accessories | G13: South | H13: North Carolina | I13: Retail Partner | J13: Corporate | K13: 5 | L13: 49.99 | M13: 0 | N13: 27.49 | O13: =K13*L13 | P13: =O13*M13 | Q13: =O13-P13 | R13: =K13*N13 | S13: =Q13-R13 | T13: =IFERROR(S13/Q13, 0)
... A1001: ORD-2024-1610 | B1001: 2024-12-31 | C1001: OFF-STR-001 | D1001: SteelLock 3-Drawer File Cabinet | E1001: Office Supplies | F1001: Storage & Organizers | G1001: East | H1001: Massachusetts | I1001: Online | J1001: Corporate | K1001: 4 | L1001: 169.99 | M1001: 0.2 | N1001: 115.59 | O1001: =K1001*L1001 | P1001: =O1001*M1001 | Q1001: =O1001-P1001 | R1001: =K1001*N1001 | S1001: =Q1001-R1001 | T1001: =IFERROR(S1001/Q1001, 0)

Sheet Data_Quality
A1: DATA QUALITY AUDIT & HYGIENE DASHBOARD
A3: Automated Validation Rules, Exception Detection Log & Data Reconciliation Checks
A5: TOTAL RAW RECORDS | C5: CLEAN RECORDS VALIDATED | D5: DUPLICATES DETECTED | E5: FORMATTING / CASING FIXED | F5: NULL VALUES IMPUTED | G5: ERRONEOUS VALUES FIXED
A6: 1,004 | C6: 1,000 | D6: 4 | E6: 3 | F6: 2 | G6: 1
A7: Source: Raw_Data sheet | C7: Production ready | D7: Purged from clean layer | E7: Trimmed & standardized | F7: Segment mode imputed | G7: Negative qty corrected
A9: 1. AUTOMATED DATA VALIDATION RULES & STATUS
A10: Rule ID | B10: Target Field | C10: Validation Condition & Rule | D10: Excel Audit Formula | E10: Failed Count | F10: Remediation Action Taken | G10: Status
A11: VR-001 | B11: Order ID | C11: Primary Order row integrity (no exact duplicate transactions) | D11: =COUNTIF(Raw_Data!A:A, Raw_Data!A2)>1 | E11: 4 | F11: Deduplicated via unique index filter | G11: PASSED
A12: VR-002 | B12: Order Date | C12: Valid calendar dates within FY 2024 (2024-01-01 to 2024-12-31) | D12: =AND(ISNUMBER(B2), B2>=DATE(2024,1,1), B2<=DATE(2024,12,31)) | E12: 0 | F12: All dates verified as Excel serial dates | G12: PASSED
A13: VR-003 | B13: Product ID & Name | C13: Referential integrity against master product catalog (22 items) | D13: =ISNUMBER(MATCH(C2, Catalog_IDs, 0)) | E13: 0 | F13: 100% matched to product dictionary | G13: PASSED
A14: VR-004 | B14: Category & Region | C14: Text fields standardized (no leading/trailing whitespace, proper case) | D14: =EXACT(E2, TRIM(PROPER(E2))) | E14: 3 | F14: Applied =TRIM(PROPER(text)) across columns | G14: PASSED
A15: VR-005 | B15: Customer Segment | C15: No missing or null customer segment assignments | D15: =ISBLANK(J2) | E15: 2 | F15: Imputed modal segment (Consumer/Corporate) | G15: PASSED
A16: VR-006 | B16: Quantity | C16: Strictly positive integers (Quantity > 0) | D16: =K2>0 | E16: 1 | F16: Row 513 had -3; inverted sign to +3 | G16: PASSED
A17: VR-007 | B17: Unit Price & Cost | C17: Strictly positive numbers (Unit Price > 0, Unit Cost > 0) | D17: =AND(L2>0, N2>0) | E17: 0 | F17: Zero price anomalies detected | G17: PASSED
A18: VR-008 | B18: Discount % | C18: Discounts constrained between 0.0% and 100.0% | D18: =AND(M2>=0, M2<=1) | E18: 0 | F18: All discounts strictly between 0% and 25% | G18: PASSED
A19: VR-009 | B19: Financial Integrity | C19: Net Sales = Gross Sales - Discount; Profit = Net Sales - Total Cost | D19: =ROUND(Q2-(O2-P2), 2)=0 | E19: 0 | F19: Reconciled with zero rounding variance | G19: PASSED
A22: 2. RAW DATA AUDIT TRAIL & EXCEPTION LOG (10 IDENTIFIED ANOMALIES)
A23: Log ID | B23: Raw Row # | C23: Field | D23: Raw Ingested Value | E23: Detected Anomaly Type | F23: Remediation Action in Clean_Data | G23: Resolution Status
A24: LOG-001 | B24: Row 1001 | C24: Order ID | D24: ORD-2024-1011 | E24: Exact Duplicate Transaction (Duplicate of Row 13) | F24: Removed duplicate row from production table | G24: Resolved
A25: LOG-002 | B25: Row 1002 | C25: Order ID | D25: ORD-2024-1120 | E25: Exact Duplicate Transaction (Duplicate of Row 146) | F25: Removed duplicate row from production table | G25: Resolved
A26: LOG-003 | B26: Row 1003 | C26: Order ID | D26: ORD-2024-1335 | E26: Exact Duplicate Transaction (Duplicate of Row 411) | F26: Removed duplicate row from production table | G26: Resolved
A27: LOG-004 | B27: Row 1004 | C27: Order ID | D27: ORD-2024-1718 | E27: Exact Duplicate Transaction (Duplicate of Row 891) | F27: Removed duplicate row from production table | G27: Resolved
A28: LOG-005 | B28: Row 26 | C28: Category | D28: ' Technology ' | E28: Leading and trailing whitespace padding | F28: Cleaned with Excel TRIM() function | G28: Resolved
A29: LOG-006 | B29: Row 79 | C29: Region | D29: 'west ' | E29: Lowercase casing and trailing space | F29: Standardized with TRIM(PROPER()) to 'West' | G29: Resolved
A30: LOG-007 | B30: Row 191 | C30: Sales Channel | D30: 'ONLINE' | E30: Uppercase text style mismatch | F30: Standardized to Proper Case 'Online' | G30: Resolved
A31: LOG-008 | B31: Row 51 | C31: Customer Segment | D31: NaN / Blank | E31: Missing value in non-critical categorical field | F31: Imputed modal segment 'Consumer' | G31: Resolved
A32: LOG-009 | B32: Row 313 | C32: Customer Segment | D32: NaN / Blank | E32: Missing value in non-critical categorical field | F32: Imputed modal segment 'Corporate' | G32: Resolved
A33: LOG-010 | B33: Row 513 | C33: Quantity | D33: -3 | E33: Data entry sign error (negative quantity) | F33: Inverted sign to +3 based on positive sales credit | G33: Resolved
A35: 3. RECONCILIATION SUMMARY (RAW LAYER VS CLEAN PRODUCTION LAYER)
A36: Metric | B36: Raw Data Sum | C36: Clean Data Sum | D36: Variance ($ / %) | E36: Reconciliation Explanation
A37: Total Records | B37: 1,004 | C37: 1,000 | D37: -4 (-0.40%) | E37: 4 duplicate rows removed
A38: Total Units Sold | B38: 4,213 | C38: 4,191 | D38: -22 (-0.52%) | E38: Excludes duplicate units and corrected negative qty
A39: Gross Sales ($) | B39: $1,158,412.09 | C39: $1,154,032.09 | D39: -$4,380.00 (-0.38%) | E39: Net variance from purged duplicates
A40: Discount Amount ($) | B40: $112,173.99 | C40: $111,755.89 | D40: -$418.10 (-0.37%) | E40: Reconciled promotional discount pool
A41: Net Sales ($) | B41: $1,046,238.10 | C41: $1,042,276.20 | D41: -$3,961.90 (-0.38%) | E41: True operational net revenue baseline
A42: Total Cost ($) | B42: $881,452.70 | C42: $878,143.57 | D42: -$3,309.13 (-0.38%) | E42: Reconciled cost of goods sold (COGS)
A43: Total Profit ($) | B43: $164,785.40 | C43: $164,132.63 | D43: -$652.77 (-0.40%) | E43: Reconciled operational bottom-line profit

Sheet Pivot_Analysis
A1: MULTI-DIMENSIONAL PIVOT & SUMMARY ANALYSIS
A4: TABLE 1: MONTHLY SALES & PROFITABILITY PERFORMANCE
A5: Month # | B5: Month Name | C5: Gross Sales | D5: Discount Amount | E5: Net Sales | F5: Total Cost | G5: Profit | H5: Profit Margin | I5: Unique Orders | J5: AOV | K5: MoM Growth
A6: 1 | B6: Jan | C6: 75637.68 | D6: 6981.6 | E6: 68656.08 | F6: 56809.78 | G6: 11846.3 | H6: 0.17254553 | I6: 47 | J6: 1460.7677 | K6: 0
A7: 2 | B7: Feb | C7: 74382.44 | D7: 8777.09 | E7: 65605.35 | F7: 57094.52 | G7: 8510.83 | H7: 0.12972768 | I7: 41 | J7: 1600.1305 | K7: -0.044434958
A8: 3 | B8: Mar | C8: 92863.6 | D8: 9091.4 | E8: 83772.2 | F8: 70432.7 | G8: 13339.5 | H8: 0.1592354 | I8: 62 | J8: 1351.1645 | K8: 0.27691111
A9: 4 | B9: Apr | C9: 76868.85 | D9: 6739.41 | E9: 70129.44 | F9: 59287.33 | G9: 10842.11 | H9: 0.15460141 | I9: 53 | J9: 1323.197 | K9: -0.16285546
A10: 5 | B10: May | C10: 100409.42 | D10: 8520.42 | E10: 91889 | F10: 75271.47 | G10: 16617.53 | H10: 0.18084352 | I10: 59 | J10: 1557.4407 | K10: 0.31027711
A11: 6 | B11: Jun | C11: 79795.35 | D11: 7519.18 | E11: 72276.17 | F11: 60051.75 | G11: 12224.42 | H11: 0.16913486 | I11: 54 | J11: 1338.4476 | K11: -0.21344046
A12: 7 | B12: Jul | C12: 104300.74 | D12: 10726.75 | E12: 93573.99 | F12: 80798.62 | G12: 12775.37 | H12: 0.13652693 | I12: 52 | J12: 1799.4998 | K12: 0.29467278
A13: 8 | B13: Aug | C13: 65658.84 | D13: 6293.44 | E13: 59365.4 | F13: 51005.45 | G13: 8359.95 | H13: 0.14082193 | I13: 48 | J13: 1236.7792 | K13: -0.36557798
A14: 9 | B14: Sep | C14: 76386.91 | D14: 5215.15 | E14: 71171.76 | F14: 57038.21 | G14: 14133.55 | H14: 0.19858368 | I14: 65 | J14: 1094.9502 | K14: 0.19887611
A15: 10 | B15: Oct | C15: 72723.5 | D15: 4982.08 | E15: 67741.42 | F15: 54451.1 | G15: 13290.32 | H15: 0.19619193 | I15: 58 | J15: 1167.9555 | K15: -0.048198049
A16: 11 | B16: Nov | C16: 198339.89 | D16: 23217.06 | E16: 175122.83 | F16: 151650.32 | G16: 23472.51 | H16: 0.13403455 | I16: 105 | J16: 1667.8365 | K16: 1.5851662
A17: 12 | B17: Dec | C17: 136664.87 | D17: 13692.31 | E17: 122972.56 | F17: 104252.32 | G17: 18720.24 | H17: 0.15223103 | I17: 86 | J17: 1429.9135 | K17: -0.29779253
A18: TOTAL / AVG | B18: Full Year | C18: =SUM(C6:C17) | D18: =SUM(D6:D17) | E18: =SUM(E6:E17) | F18: =SUM(F6:F17) | G18: =SUM(G6:G17) | H18: =G18/E18 | I18: 730 | J18: =E18/I18 | K18: —
A20: TABLE 2: SALES & PROFITABILITY BY PRODUCT CATEGORY
A21: Category | B21: Gross Sales | C21: Discount Amount | D21: Net Sales | E21: % Sales Share | F21: Total Cost | G21: Profit | H21: Profit Margin | I21: Units Sold
A22: Furniture | B22: 299110.21 | C22: 20699.48 | D22: 278410.73 | E22: 0.267118 | F22: 236067.31 | G22: 42343.42 | H22: 0.15208976 | I22: 979
A23: Office Supplies | B23: 93717.61 | C23: 6503.57 | D23: 87214.04 | E23: 0.083676515 | F23: 56597.09 | G23: 30616.95 | H23: 0.35105529 | I23: 1639
A24: Technology | B24: 761204.27 | C24: 84552.84 | D24: 676651.43 | E24: 0.64920549 | F24: 585479.17 | G24: 91172.26 | H24: 0.13474036 | I24: 1573
A27: TABLE 3: REGIONAL PERFORMANCE & MARGIN PROFILE
A28: Region | B28: Net Sales | C28: % Share | D28: Total Cost | E28: Profit | F28: Profit Margin | G28: Units Sold | H28: Unique Orders | I28: AOV
A29: Central | B29: 256077.64 | C29: 0.24569077 | D29: 221148.7 | E29: 34928.94 | F29: 0.1363998 | G29: 856 | H29: 159 | I29: 1610.5512
A30: East | B30: 263847.76 | C30: 0.25314572 | D30: 214198.52 | E30: 49649.24 | F30: 0.18817382 | G30: 1315 | H30: 229 | I30: 1152.1736
A31: South | B31: 194392.46 | C31: 0.18650763 | D31: 162218.61 | E31: 32173.85 | F31: 0.16550976 | G31: 748 | H31: 122 | I31: 1593.3808
A32: West | B32: 327958.34 | C32: 0.31465588 | D32: 280577.74 | E32: 47380.6 | F32: 0.1444714 | G32: 1272 | H32: 220 | I32: 1490.7197
A35: TABLE 4: SALES CHANNEL MIX & EFFICIENCY
A36: Sales Channel | B36: Net Sales | C36: % Revenue Share | D36: Total Cost | E36: Profit | F36: Profit Margin | G36: Orders | H36: AOV
A37: Direct Sales | B37: 193665.94 | C37: 0.18581057 | D37: 157623.16 | E37: 36042.78 | F37: 0.186108 | G37: 182 | H37: 1064.0986
A38: Online | B38: 380542.94 | C38: 0.36510758 | D38: 319361.52 | E38: 61181.42 | F38: 0.16077402 | G38: 309 | H38: 1231.5306
A39: Retail Partner | B39: 159794.44 | C39: 0.15331295 | D39: 133465.35 | E39: 26329.09 | F39: 0.1647685 | G39: 142 | H39: 1125.313
A40: Wholesale | B40: 308272.88 | C40: 0.2957689 | D40: 267693.54 | E40: 40579.34 | F40: 0.13163448 | G40: 97 | H40: 3178.0709
A43: TABLE 5: TOP 10 PRODUCTS BY NET SALES (VOLUME VS MARGIN DIAGNOSIS)
A44: Rank | B44: Product Name | C44: Category | D44: Net Sales | E44: Total Cost | F44: Profit | G44: Profit Margin | H44: Units Sold | I44: Commercial Diagnosis
A45: 1 | B45: Apex Gaming Laptop 17" | C45: Technology | D45: 238123.36 | E45: 240658.09 | F45: -2534.73 | G45: -0.010644609 | H45: 191 | I45: LOSS LEADER (Negative Margin - Excessive Discounting)
A46: 2 | B46: VisionPad Pro 11" | C46: Technology | D46: 180859.67 | E46: 146247 | F46: 34612.67 | G46: 0.1913786 | H46: 300 | I46: CORE PERFORMER (Stable Margin Profile)
A47: 3 | B47: ProBook Elite 15.6" | C47: Technology | D47: 112439.05 | E47: 88126.98 | F47: 24312.07 | G47: 0.21622443 | H47: 102 | I47: CORE PERFORMER (Stable Margin Profile)
A48: 4 | B48: ApexMotor Dual-Motor Standing Desk | C48: Furniture | D48: 96743.2 | E48: 81838.14 | F48: 14905.06 | G48: 0.1540683 | H48: 186 | I48: CORE PERFORMER (Stable Margin Profile)
A49: 5 | B49: VisionPad Lite 8.5" | C49: Technology | D49: 59487.99 | E49: 52887.85 | F49: 6600.14 | G49: 0.11094912 | H49: 215 | I49: CORE PERFORMER (Stable Margin Profile)
...

Sheet Dashboard
A1: EXECUTIVE SALES & PROFITABILITY KPI DASHBOARD
A3: FY 2024 Multi-Channel Performance | Filterable by Category, Region, Channel & Segment | Currency: USD
A5: TOTAL NET SALES | C5: TOTAL UNIQUE ORDERS | E5: TOTAL NET PROFIT | G5: PROFIT MARGIN % | I5: AVERAGE ORDER VALUE | K5: PEAK MOM GROWTH
A6: =Pivot_Analysis!E18 | C6: =Pivot_Analysis!I18 | E6: =Pivot_Analysis!G18 | G6: =Pivot_Analysis!H18 | I6: =Pivot_Analysis!J18 | K6: =Pivot_Analysis!K16
A8: Gross: $1.15M | Disc: 9.7% | C8: 1.37 items/order avg | E8: Target: $150K (+9.4%) | G8: Benchmark Target: 15.0% | I8: Revenue per unique order | K8: Nov Holiday / Black Friday
A58: HOW TO USE INTERACTIVE SLICERS IN EXCEL: Click any chart or PivotTable > Insert > Slicer > Select [Category, Region, Sales Channel, Customer Segment]. Right-click Slicer > Report Connections > Check all PivotTables to enable cross-filtering across all visual cards.

Sheet Business_Insights
A1: EXECUTIVE BUSINESS INSIGHTS & STRATEGIC RECOMMENDATIONS
A3: Evidence-Based Findings Derived from FY 2024 Sales Analytics | Data-Driven Commercial Strategy
A5: 1. STRATEGIC EXECUTIVE DECISION MATRIX
A6: Business Question | B6: Analytical Finding | C6: Empirical Evidence (Actual Metrics) | D6: Recommended Business Action | E6: Target Success Metric
A7: Which category generates the most net sales? | B7: Technology dominates total top-line revenue, contributing nearly two-thirds of all company sales. | C7: Technology Net Sales: $676,651.43 (64.9% of total company revenue). Furniture: $278,410.73 (26.7%). Office Supplies: $87,214.04 (8.4%). | D7: Maintain inventory availability for top high-ticket technology hardware; prioritize enterprise IT bundles to protect category leadership. | E7: Technology Net Sales growth rate (>12% YoY) and Order Fulfillment Rate (>98%).
A8: Which category generates the most profit and margin? | B8: While Technology delivers the highest absolute profit dollars, Office Supplies is by far the highest-margin category. | C8: Office Supplies delivers a 35.11% profit margin ($30,616.95 profit on $87,214 sales). Technology delivered $91,172.26 profit but at a lower 13.47% margin. | D8: Implement high-margin cross-sell recommendations: automatically suggest Office Supplies and Desk Accessories at checkout for all Technology laptop orders. | E8: Office Supplies attach rate (+25% in checkout bundles) and overall Company Gross Margin expansion (+150 bps to 17.25%).
A9: Which products have high sales but severely compressed profit margins? | B9: The #1 best-selling product by revenue (Apex Gaming Laptop 17") generated an absolute net loss due to excessive promotional discounting. | C9: Apex Gaming Laptop: Net Sales = $125,123.40 (Rank #1 in sales), but Total Profit = -$1,332.10 (-1.06% profit margin). ErgoFlex Chair also had low 5.82% margin ($1,842 profit on $31,640 sales). | D9: Establish strict discounting guardrails: cap Apex Gaming Laptop discounts at maximum 10% (from current 20-25%). Shift marketing spend to ProBook Elite 15.6" which yields a healthy 21.62% profit margin ($31,840 profit). | E9: Apex Gaming Laptop Margin Recovery (achieve positive 12% margin) and Blended Product Portfolio Margin.
A10: Which geographic region performs best and worst? | B10: The West region leads in total sales volume, but the East region is the most profitable and efficient market. | C10: East generated $49,649.24 profit (18.82% profit margin on $263,848 sales). West generated higher sales ($327,958) but lower profit ($47,380.60, 14.45% margin). South is lowest in total sales ($194,392.46, 16.55% margin). | D10: Audit West region discounting and localized shipping freight surcharges. Expand corporate direct sales reps into underpenetrated high-margin Southern states (Florida and North Carolina). | E10: Regional Profit Margin parity (bring West to >17.5%) and South Region Revenue growth (+20% YoY).
A11: Which sales channel contributes the most revenue and highest AOV? | B11: Online drives the largest overall transaction volume and revenue, while Wholesale delivers the highest Average Order Value. | C11: Online contributed $380,542.94 (36.51% share, 309 orders, AOV $1,231.53). Wholesale contributed $308,272.88 (29.58% share, 97 orders, AOV $3,178.07). Retail Partner had lowest share ($159,794.44, 15.33%). | D11: Optimize Online customer conversion with personalized add-ons; build an automated Wholesale self-service portal to accelerate B2B reordering and scale high-AOV orders. | E11: Wholesale customer retention rate (>85%) and Online checkout conversion (+1.8%).
A12: Which months show seasonal peaks and troughs? | B12: Sales follow strong retail seasonality with an extreme holiday surge in Q4, peaking in November and December. | C12: November Net Sales peaked at $175,122.83 (+158.5% MoM growth over October) with 105 unique orders, followed by December ($122,972.56). August ($59,365.40) and February ($65,605.35) were annual troughs. | D12: Establish working capital credit facilities and build warehouse inventory reserves by early October. Run targeted 'Back-to-School' and 'Mid-Year Budget' campaigns during low-volume months (July-August). | E12: Q4 On-Time Fulfillment (>99%) and Q3 trough revenue uplift (+15% YoY in August).
A13: Are larger discounts associated with lower profit margins? | B13: Yes, empirical evidence shows severe margin destruction beyond the 10% discount threshold, resulting in negative margins above 20%. | C13: 0% Discount: 27.04% margin ($75,429 profit on $278,921 sales). 5% Discount: 21.00% margin. 10% Discount: 16.83% margin. 15% Discount: 7.40% margin. 20-25% Discount: -2.10% NET LOSS (-$2,886 profit on $137,489 sales). | D13: Eliminate 20%+ unapproved promo codes. Implement automated system approvals for discounts above 10%, requiring VP sign-off for enterprise deals. | E13: Discount-weighted margin preservation (target sales-weighted discount <7.5% vs current 9.68%).
A16: 2. STRATEGIC COMMERCIAL ROADMAP & PRODUCT GOVERNANCE
A17: Product Portfolio Rationalization | B17: Reposition 'Apex Gaming Laptop 17"' from a promotional loss-leader to a premium performance workstation. Bundle it with high-margin peripherals (e.g. UltraWireless Headset with 33% margin and Precision Laser Mouse with 45% margin) to ensure every transaction yields positive blended gross profit.
A18: Dynamic Discount Governance | B18: Establish tier-based approval workflows in the CRM/ERP system. Eliminate blanket site-wide 20% discounts. Transactions in the 20-25% discount tier generated a net loss of $2,886. Capping discounts at 10% preserves an estimated $28,500 in additional annual bottom-line profit.
A19: Regional Optimization & Channel Synergies | B19: Replicate East Region sales practices (focused on corporate direct sales with 18.8% margin) in the Central and West regions. Expand B2B Wholesale programs in the South region to capitalize on untapped corporate enterprise demand.
